2025-01-23 16:10:33,968 INFO    StreamThr :751233 [internal.py:wandb_internal():85] W&B internal server running at pid: 751233, started at: 2025-01-23 16:10:33.966921
2025-01-23 16:10:33,970 DEBUG   HandlerThread:751233 [handler.py:handle_request():158] handle_request: status
2025-01-23 16:10:33,976 INFO    WriterThread:751233 [datastore.py:open_for_write():87] open: /common/home/hg343/Research/accelerate_combo_option/src/wandb/run-20250123_161033-jj4k03ed/run-jj4k03ed.wandb
2025-01-23 16:10:33,977 DEBUG   SenderThread:751233 [sender.py:send():378] send: header
2025-01-23 16:10:33,997 DEBUG   SenderThread:751233 [sender.py:send():378] send: run
2025-01-23 16:10:34,088 ERROR   SenderThread:751233 [internal_api.py:execute():344] 404 response executing GraphQL.
2025-01-23 16:10:34,089 ERROR   SenderThread:751233 [internal_api.py:execute():345] {"errors":[{"message":"entity single_stock_frontier_data not found during upsertBucket","path":["upsertBucket"]}],"data":{"upsertBucket":null}}
2025-01-23 16:10:34,089 ERROR   SenderThread:751233 [sender.py:send_run():970] It appears that you do not have permission to access the requested resource. Please reach out to the project owner to grant you access. If you have the correct permissions, verify that there are no issues with your networking setup.(Error 404: Not Found)
Traceback (most recent call last):
  File "/common/home/hg343/anaconda3/lib/python3.9/site-packages/wandb/sdk/lib/retry.py", line 131, in __call__
    result = self._call_fn(*args, **kwargs)
  File "/common/home/hg343/anaconda3/lib/python3.9/site-packages/wandb/sdk/internal/internal_api.py", line 340, in execute
    return self.client.execute(*args, **kwargs)  # type: ignore
  File "/common/home/hg343/anaconda3/lib/python3.9/site-packages/wandb/vendor/gql-0.2.0/wandb_gql/client.py", line 52, in execute
    result = self._get_result(document, *args, **kwargs)
  File "/common/home/hg343/anaconda3/lib/python3.9/site-packages/wandb/vendor/gql-0.2.0/wandb_gql/client.py", line 60, in _get_result
    return self.transport.execute(document, *args, **kwargs)
  File "/common/home/hg343/anaconda3/lib/python3.9/site-packages/wandb/sdk/lib/gql_request.py", line 59, in execute
    request.raise_for_status()
  File "/common/home/hg343/anaconda3/lib/python3.9/site-packages/requests/models.py", line 1024, in raise_for_status
    raise HTTPError(http_error_msg, response=self)
requests.exceptions.HTTPError: 404 Client Error: Not Found for url: https://api.wandb.ai/graphql

During handling of the above exception, another exception occurred:

Traceback (most recent call last):
  File "/common/home/hg343/anaconda3/lib/python3.9/site-packages/wandb/sdk/internal/sender.py", line 968, in send_run
    server_run = self._init_run(run, config_value_dict)
  File "/common/home/hg343/anaconda3/lib/python3.9/site-packages/wandb/sdk/internal/sender.py", line 1013, in _init_run
    server_run, inserted, server_messages = self._api.upsert_run(
  File "/common/home/hg343/anaconda3/lib/python3.9/site-packages/wandb/apis/normalize.py", line 73, in wrapper
    raise err
  File "/common/home/hg343/anaconda3/lib/python3.9/site-packages/wandb/apis/normalize.py", line 41, in wrapper
    return func(*args, **kwargs)
  File "/common/home/hg343/anaconda3/lib/python3.9/site-packages/wandb/sdk/internal/internal_api.py", line 2188, in upsert_run
    response = self.gql(
  File "/common/home/hg343/anaconda3/lib/python3.9/site-packages/wandb/sdk/internal/internal_api.py", line 312, in gql
    ret = self._retry_gql(
  File "/common/home/hg343/anaconda3/lib/python3.9/site-packages/wandb/sdk/lib/retry.py", line 147, in __call__
    retry_timedelta_triggered = check_retry_fn(e)
  File "/common/home/hg343/anaconda3/lib/python3.9/site-packages/wandb/util.py", line 965, in check_retry_fn
    return fallback_retry_fn(e)
  File "/common/home/hg343/anaconda3/lib/python3.9/site-packages/wandb/util.py", line 907, in no_retry_auth
    raise CommError(
wandb.errors.CommError: It appears that you do not have permission to access the requested resource. Please reach out to the project owner to grant you access. If you have the correct permissions, verify that there are no issues with your networking setup.(Error 404: Not Found)
2025-01-23 16:10:34,130 DEBUG   HandlerThread:751233 [handler.py:handle_request():158] handle_request: shutdown
2025-01-23 16:10:34,130 INFO    HandlerThread:751233 [handler.py:finish():882] shutting down handler
2025-01-23 16:10:34,997 INFO    WriterThread:751233 [datastore.py:close():296] close: /common/home/hg343/Research/accelerate_combo_option/src/wandb/run-20250123_161033-jj4k03ed/run-jj4k03ed.wandb
2025-01-23 16:10:35,092 INFO    SenderThread:751233 [sender.py:finish():1545] shutting down sender
