
Generating frontier for markets:   0%|                                                                                                                                                      | 0/20 [00:00<?, ?it/s]
There are 25 buy orders and 25 sell orders
#####Generating combinatorial/book/STOCK_2_SEED_2_book_AAPL_MSFT.npy with size 50 and noise 0.015625#####
Starting async computation for iteration 0
Set parameter Username
Academic license - for non-commercial use only - expires 2025-11-08
RangeIndex(start=0, stop=25, step=1) {2, 15}
RangeIndex(start=0, stop=25, step=1) {4, 8, 9, 10, 15, 19, 20, 22}
23
17
Generating frontier for markets:   0%|                                                                                                                                                      | 0/20 [00:01<?, ?it/s]
Traceback (most recent call last):
  File "/common/home/hg343/anaconda3/lib/python3.9/site-packages/pandas/core/indexes/base.py", line 3802, in get_loc
    return self._engine.get_loc(casted_key)
  File "pandas/_libs/index.pyx", line 138, in pandas._libs.index.IndexEngine.get_loc
  File "pandas/_libs/index.pyx", line 165, in pandas._libs.index.IndexEngine.get_loc
  File "pandas/_libs/hashtable_class_helper.pxi", line 5745, in pandas._libs.hashtable.PyObjectHashTable.get_item
  File "pandas/_libs/hashtable_class_helper.pxi", line 5753, in pandas._libs.hashtable.PyObjectHashTable.get_item
KeyError: 0
The above exception was the direct cause of the following exception:
Traceback (most recent call last):
  File "/common/home/hg343/Research/accelerate_combo_option/src/combo_stock_frontier_data_preprocessor.py", line 498, in <module>
    synthetic_combo_frontier_generation(opt_buy_book, opt_sell_book)
  File "/common/home/hg343/Research/accelerate_combo_option/src/combo_stock_frontier_data_preprocessor.py", line 114, in synthetic_combo_frontier_generation
    num_buy_holder, num_sell_holder, num_stock = len(opt_buy_book_holder), len(opt_sell_book_holder), len(opt_buy_book_holder[0])-4
  File "/common/home/hg343/anaconda3/lib/python3.9/site-packages/pandas/core/frame.py", line 3807, in __getitem__
    indexer = self.columns.get_loc(key)
  File "/common/home/hg343/anaconda3/lib/python3.9/site-packages/pandas/core/indexes/base.py", line 3804, in get_loc
    raise KeyError(key) from err
KeyError: 0